Workbook

Sheet Raw_laptops_Dataset
A1: Brand: | B1: Product name | C1: Processor | D1: Video graphics | E1: Video graphics Memorey | F1: RAM | G1: Hard drive | H1: Display | I1: Display Resolution | J1: Display Refresh Rate | K1: Operating System | L1: Keyboard | M1: Battery | N1: Webcam | O1: Connections | P1: Dimensions | Q1: Weight | R1: Colors | S1: Warranty | T1: Price | U1: Processor Generation | V1: Processor Details | W1: Product number | X1: Power supply type | Y1: Laptop Color | Z1: Finger Print | AA1: SUPPORT SSD M2 | AB1: Pointing device | AC1: Optical drive | AD1: Series :
A2: MSI | B2: Titan 18 HX Dragon Edition Norse Myth A2XWJG | C2: Intel Core Ultra 9 285HX | D2: Nvidia GeForce RTX 5090 24GB | E2: 24GB GDDR7 | F2: 96GB DDR5 6400MHz 48GB*2 | G2: 6TB, 2TB NVMe PCIe Gen5x4 SSD w/o DRAM + 2TB NVMe PCIe Gen4x4 SSD x2 | H2: 18" 16:10 UHD+ (3840x2400), MiniLED, 120Hz, 100% DCI-P3 (Typ.), IPS-Level panel | I2: 3840x2400 | J2: 120 Hz | K2: Windows® 11 Home | L2: Cherry Mechanical Per-Key RGB Gaming Keyboard by SteelSeries | M2: 4-Cell 99 Battery (Whr) | N2: IR FHD type (30fps@1080p) with HDR 3D Noise Reduction+ (3DNR+) | O2: 2x Thunderbolt™ 5 (DisplayPort™/ Power Delivery 3.1) 3x Type-A USB3.2 Gen2 1x SD Express Card Reader 1x HDMI™ 2.1 (8K @ 60Hz / 4K @ 120Hz) | P2: 404 x 307.5 x 24-32.05 mm | Q2: 3.6 kg | R2: Core Black | S2: 2 Year | T2: 320000
A3: MSI | B3: Katana 15 HX 14XWGK | C3: Intel Core i9-14900HX | D3: Nvidia GeForce RTX 5070 8GB | E3: 8GB GDDR7 | F3: 16GB DDR5 8GB*2 | G3: 1TB NVMe PCIe SSD Gen4x4 | H3: 15.6" QHD (2560*1440), 165Hz DCI-P3 100% typical | I3: 2560*1440 | J3: 165 HZ | K3: Windows® 11 Home | L3: 4-Zone RGB Gaming Keyboard | M3: 4 cell, 75Whr | N3: HD Webcam (720p @ 30fps) | O3: 1x USB Type-C (USB 3.2 Gen2 / DisplayPort / Power Delivery 3.0) 3x USB Type-A (USB 3.2 Gen2) 1x HDMI 2.1 (8K@60Hz / 4K@120Hz) 1x Mic-in/Headphone-out Combo Jack 1x RJ45 (Gb LAN) | P3: 359 x 262 x 25.5 mm | Q3: 2.4 kg | R3: Black | S3: 2 Year | T3: 79999 | U3: 14th generation
A4: Acer | B4: NITRO V15-ANV15-51-51H9 | C4: Intel Core I5-13420H | D4: Nvidia GeForce RTX 4050 6GB | E4: 6GB GDDR6 | F4: 8 GB DDR5-SDRAM | G4: 512 GB SSD | H4: 15.6'' Inch FHD IPS LED backlight aspect ratio 16:9 refresh rate 144 Hz | I4: 1920x1080 | J4: 144 Hz | K4: Windows® 11 Home | M4: 57 Wh | O4: USB 3.2 Gen 1 (3.1 Gen 1) Type-A ports quantity 3 HDMI ports quantity 1 USB 3.2 Gen 2 (3.1 Gen 2) Type-C ports quantity 1 Ethernet LAN (RJ-45) ports 1 | R4: Black | S4: 1 Year | T4: 39999 | U4: 13th generation | V4: 8C (4P + 4E) / 12T, P-core 2.1 / 4.6GHz, E-core 1.5 / 3.4GHz, 12MB
A5: Dell | B5: Alienware 16 Aurora AC16250 | C5: Intel Core 7 240H | D5: NVIDIA(R) GeForce RTX(TM) 5050 | E5: 8 GB GDDR7 | F5: 16GB, 2x8GB, DDR5, 5600 MT/s ( 5200 MT/s with Intel Core 5 CP U) | G5: 512GB M.2 PCIe NVMe SSD | H5: 16" WQXGA 120Hz, 300 nits, ComfortView Plus, 1 00% sRGB color gamut | I5: 2560 x 1600 | J5: 120 Hz | K5: Windows 11 Home | M5: 6-Cell Battery, 96 Whr (Integr ated) | O5: 2 USB 3.2 Gen 1 (5 Gbps) ports 1 USB 3.2 Gen 2 (10 Gbps) Type-C® port with DisplayPort™ 1.4a ports 1 USB 3.2 Gen 2 (10 Gbps) Type-C® port with Power Delivery 1 HDMI 2.1 port with Discrete Graphics Controller Direct Output 1 universal audio jack (RCA, 3.5 | P5: 356.98 x 265.43 x 15.20 mm | Q5: 2.49 kg | S5: 1 Year | T5: 57999 | V5: 240H (24MB cache, 1 0 cores, 1.80 to 5.20 GHz P-Co re)
A6: Dell | B6: Alienware 16 Aurora AC16250 | C6: Intel Core 9 270H | D6: Nvidia GeForce RTX 5060 8GB | E6: 8GB GDDR7 | F6: 16GB, 2x8GB, DDR5, 5600 MT/s | G6: 1TB M.2 PCIe NVMe SSD | H6: 16" WQXGA 120Hz, 300 nits, ComfortView Plus, 100% sRGB color gamut | I6: 2560 x 1600 | J6: 120 Hz | K6: DOS | L6: Alienware White Backlit Keyboard | M6: 6-Cell Battery, 96 Whr (Integrated) | N6: 720p at 30 fps HD camera, Dual-array microphones | O6: 2 USB Type-A 3.2 Gen 1 Port 1 Type-C® Port (USB 3.2 Gen 2, DisplayPort™ 1.4) (iGPU) 1 Type-C® Port (USB 3.2 Gen 2, DisplayPort™ 1.4a) (iGPU) 1 HDMI 2.1 (dGPU) 1 Power/DC-in Port 1 RJ-45 Ethernet 1 Global headset jack | P6: 356.98 x 265.43 x 22.70 mm | Q6: 2.49 kg | S6: 1 Year | T6: 89999 | V6: 24MB cache, 14 cores, 2.00 to 5.80 GHz P-Core
A7: Dell | B7: Alienware 16 Aurora AC16250 | C7: Intel Core 7 240H | D7: Nvidia GeForce RTX 5060 | E7: 8 GB GDDR7 | F7: 32GB, 2x16GB, DDR5, 5600 MT/s | G7: 1TB M.2 PCIe NVMe SSD | H7: 16" WQXGA 120Hz, 300 nits, ComfortView Plus, 1 00% sRGB color gamut | I7: 2560 x 1600 | J7: 120 Hz | K7: DOS | M7: 6-Cell Battery, 96 Whr (Integr ated) | O7: 2 USB 3.2 Gen 1 (5 Gbps) ports 1 USB 3.2 Gen 2 (10 Gbps) Type-C® port with DisplayPort™ 1.4a ports 1 USB 3.2 Gen 2 (10 Gbps) Type-C® port with Power Delivery 1 HDMI 2.1 port with Discrete Graphics Controller Direct Output 1 universal audio jack (RCA, 3.5 | P7: 356.98 x 265.43 x 15.20 mm | Q7: 2.49 kg | S7: 1 Year | T7: 67999 | V7: 240H (24MB cache, 1 0 cores, 1.80 to 5.20 GHz P-Co re)
A8: Dell | B8: Alienware 16 Aurora AC16250 | C8: Intel Core 7 240H | D8: Nvidia GeForce RTX 5050 | E8: 8 GB GDDR7 | F8: 16GB, 2x8GB, DDR5, 5600 MT/s ( 5200 MT/s with Intel Core 5 CP U) | G8: 1TB M.2 PCIe NVMe SSD | H8: 16" WQXGA 120Hz, 300 nits, ComfortView Plus, 100% sRGB color gamut | I8: 2560 x 1600 | J8: 120Hz | K8: DOS | M8: 6-Cell Battery, 96 Whr (Integr ated) | O8: 2 USB 3.2 Gen 1 (5 Gbps) ports 1 USB 3.2 Gen 2 (10 Gbps) Type-C® port with DisplayPort™ 1.4a ports 1 USB 3.2 Gen 2 (10 Gbps) Type-C® port with Power Delivery 1 HDMI 2.1 port with Discrete Graphics Controller Direct Output 1 universal audio jack (RCA, 3.5 | P8: 356.98 x 265.43 x 15.20 mm | Q8: 2.49 kg | S8: 1 Year | T8: 57999 | V8: 240H (24MB cache, 1 0 cores, 1.80 to 5.20 GHz P-Co re)
A9: HP | B9: Victus 15-fa2318TX | C9: Intel® Core™ i7-13620H | D9: NVIDIA® GeForce RTX™ 3050 | E9: 6 GB GDDR6 | F9: 16 GB DDR4-3200 MT/s (1 x 16 GB) | G9: 512 GB PCIe® Gen4 NVMe™ M.2 SSD | H9: 39.6 cm (15.6") diagonal, FHD, 144 Hz, IPS, micro-edge, anti-glare, 300 nits, 62.5% sRGB | I9: 1920 x 1080 | J9: 144 Hz | K9: Dos | L9: Full-size, backlit, moonstone gray keyboard with numeric keypad | M9: 3-cell, 52.5 Wh Li-ion polymer | N9: HP Wide Vision 720p HD camera with temporal noise reduction and integrated dual array digital microphones | O9: 1 USB Type-A 5Gbps signaling rate (HP Sleep and Charge); 1 USB Type-A 5Gbps signaling rate; 1 AC smart pin; 1 HDMI 2.1; 1 headphone/microphone combo; 1 RJ-45; 1 USB Type-C® 5Gbps signaling rate (DisplayPort™ 1.4a, HP Sleep and Charge) 10 | P9: 357.9 x 255 x 23.5 mm | Q9: 2.29 kg | R9: Mica silver | S9: 1 year | T9: 40999 | U9: 13th generation | V9: up to 4.9 GHz with Intel® Turbo Boost Technology, 24 MB L3 cache, 10 cores, 16 threads | W9: C34KHPA
A10: HP | B10: Victus 16-r1042ne | C10: Intel® Core™ i7-14700HX | D10: NVIDIA® GeForce RTX™ 4050 | E10: 6 GB GDDR6 | F10: 16 GB DDR5-5600 MT/s (2 x 8 GB) Transfer rates up to 5600 MT/s. 2 x 8 GB | G10: 512 GB PCIe® Gen4 NVMe™ TLC M.2 SSD | H10: 16.1''inch FHD | I10: 1920 x 1080 | J10: 144 Hz | K10: Dos | L10: Full-size, backlit, moonstone grey keyboard with numeric keypad | M10: 4-cell, 70 Wh Li-ion polymer | N10: HP True Vision 1080p FHD camera with temporal noise reduction and integrated dual array digital microphones | O10: 1 USB Type-A 5Gbps signaling rate (HP Sleep and Charge); 1 USB Type-C® 5Gbps signaling rate (USB Power Delivery, DisplayPort™ 1.4, HP Sleep and Charge); 2 USB Type-A 5Gbps signaling rate; 1 HDMI 2.1; 1 RJ-45; 1 AC smart pin; 1 headphone/microphone combo | Q10: 2.31 kg | R10: Mica silver | S10: 1 year | T10: 51499 | U10: 14th generation | V10: up to 5.5 GHz with Intel® Turbo Boost Technology, 33 MB L3 cache, 20 cores, 28 threads | W10: A7KC6EA
A11: HP | B11: Victus 15-FA2317TX | C11: Intel® Core™ i7-13620H | D11: NVIDIA® GeForce RTX™ 4050 | E11: 6 GB GDDR6 | F11: 16 GB DDR4-3200 MT/s (1 x 16 GB) Transfer rates up to 3200 MT/s. 1 x 16 GB | G11: 512 GB PCIe® Gen4 NVMe™ M.2 SSD | H11: 15.6'' Inch FHD | I11: 1920 x 1080 | J11: 144 Hz | K11: DOS | L11: Full-size, backlit, moonstone gray keyboard with numeric keypad | M11: 4-cell, 70 Wh Li-ion polymer | N11: HP Wide Vision 720p HD camera with temporal noise reduction and integrated dual array digital microphones | O11: 1 USB Type-A 5Gbps signaling rate (HP Sleep and Charge); 1 USB Type-A 5Gbps signaling rate; 1 AC smart pin; 1 HDMI 2.1; 1 headphone/microphone combo; 1 RJ-45; 1 USB Type-C® 5Gbps signaling rate (DisplayPort™ 1.4a, HP Sleep and Charge) | P11: 35.79 x 25.5 x 2.35 cm | Q11: 2.29 kg | R11: Mica silver | S11: 1 Year | T11: 47777 | U11: 13th generation | V11: up to 4.9 GHz with Intel® Turbo Boost Technology, 24 MB L3 cache, 10 cores, 16 threads | W11: C34K7PA
A12: Lenovo | B12: LOQ 15IAX9E | C12: Intel® Core™ i5-12450HX | D12: Nvidia GeForce RTX 3050 6GB | E12: 6GB GDDR6 | F12: 1x 16GB SO-DIMM DDR5-4800 | G12: 512GB SSD M.2 2242 PCIe® 4.0x4 NVMe® | H12: 15.6" FHD (1920x1080) IPS 300nits Anti-glare, 100% sRGB, 144Hz | I12: 1920 x 1080 | J12: 144 Hz | K12: Windows 11 Home | L12: White Backlit, Arabic | M12: Integrated 57Wh | N12: HD 720p with Privacy Shutter | O12: 2x USB-A (USB 5Gbps / USB 3.2 Gen 1) 1x USB-C® (USB 5Gbps / USB 3.2 Gen 1), data transfer only 1x HDMI® 2.1, up to 8K/60Hz 1x Headphone / microphone combo jack (3.5mm) 1x Ethernet (RJ-45) 1x Card reader 1x Power connector | P12: 359.3 x 236 x 19.9-22.95 mm | Q12: 1.77 kg | R12: Luna Grey | S12: 2 Years | T12: 31999 | U12: 12th generation | V12: 8C (4P + 4E) / 12T, P-core up to 4.4GHz, E-core up to 3.1GHz, 12MB | W12: 83LK0060ED
A13: HP | B13: Victus 16-r1066ne | C13: Intel® Core™ i5-14450HX | D13: NVIDIA® GeForce RTX™ 3050 | E13: 6 GB GDDR6 | F13: 16 GB DDR5-5600 MT/s (2 x 8 GB) Transfer rates up to 5600 MT/s. 2 x 8 GB | G13: 1 TB PCIe® Gen4 NVMe™ M.2 SSD | H13: 16.1″diagonal, FHD , 144 Hz, IPS, micro-edge, anti-glare, 300 nits, 62.5% sRGB | I13: 1920 x 1080 | J13: 144 Hz | K13: DOS | L13: Full-size, backlit, moonstone gray keyboard with numeric keypad | M13: 4-cell, 70 Wh Li-ion polymer | N13: HP True Vision 1080p FHD camera with temporal noise reduction and integrated dual array digital microphones | O13: 1 USB Type-A 5Gbps signaling rate (HP Sleep and Charge); 1 USB Type-C® 5Gbps signaling rate (USB Power Delivery, DisplayPort™ 1.4, HP Sleep and Charge); 2 USB Type-A 5Gbps signaling rate; 1 HDMI 2.1; 1 RJ-45; 1 AC smart pin; 1 headphone/microphone combo | P13: 369 x 259.4 x 22.9 mm | Q13: 2.31 kg | R13: Mica silver | S13: 1 Year | T13: 39666 | U13: 14th generation | V13: up to 4.8 GHz with Intel® Turbo Boost Technology, 20 MB L3 cache, 10 cores, 16 threads | W13: B0VX8EA
A14: HP | B14: Victus 16-r1062ne | C14: Intel® Core™ i5-14450HX | D14: NVIDIA® GeForce RTX™ 3050 | E14: 6 GB GDDR6 | F14: 16 GB DDR5-5600 MT/s (2 x 8 GB) Transfer rates up to 5600 MT/s. 2 x 8 GB | G14: 1 TB PCIe® Gen4 NVMe™ M.2 SSD | H14: 16.1″ diagonal, FHD, 144 Hz, IPS, micro-edge, anti-glare, 300 nits, 62.5% sRGB | I14: 1920 x 1080) | J14: 144 Hz | K14: DOS | L14: Full-size, backlit, performance blue opaque keyboard with numeric keypad | M14: 4-cell, 70 Wh Li-ion polymer | N14: HP True Vision 1080p FHD camera with temporal noise reduction and integrated dual array digital microphones | O14: 1 USB Type-A 5Gbps signaling rate (HP Sleep and Charge); 1 USB Type-C® 5Gbps signaling rate (USB Power Delivery, DisplayPort™ 1.4, HP Sleep and Charge); 2 USB Type-A 5Gbps signaling rate; 1 HDMI 2.1; 1 RJ-45; 1 AC smart pin; 1 headphone/microphone combo | P14: 369 x 259.4 x 22.9 mm | Q14: 2.31 kg | R14: Performance blue | S14: 1 Year | T14: 39666 | U14: 14th generation | V14: up to 4.8 GHz with Intel® Turbo Boost Technology, 20 MB L3 cache, 10 cores, 16 threads | W14: A95G4EA
A15: HP | B15: Victus 15-fa1103ne | C15: Intel® Core™ i5-13420H | D15: NVIDIA® GeForce RTX™ 3050 | E15: 6 GB GDDR6 | F15: 8 GB DDR4-3200 MT/s (1 x 8 GB) Transfer rates up to 3200 MT/s. 1 x 8 GB | G15: 512 GB PCIe® Gen4 NVMe™ M.2 SSD | H15: 15.6″ FHD (1920 × 1080), IPS, 144 Hz, 9 ms, anti-glare, 250 nits, 45% NTSC | I15: 1920 x 1080 | J15: 144 Hz | K15: DOS | L15: Full-size, backlit, performance blue keyboard with numeric keypad | M15: 4-cell, 70 Wh Li-ion polymer | N15: HP Wide Vision 720p HD camera with temporal noise reduction and integrated dual array digital microphones | O15: 1 USB Type-A 5Gbps signaling rate; 1 USB Type-A 5Gbps signaling rate (HP Sleep and Charge); 1 USB Type-C® 5Gbps signaling rate (DisplayPort™ 1.4, HP Sleep and Charge); 1 HDMI 2.1; 1 RJ-45; 1 AC smart pin; 1 headphone/microphone combo | P15: 357 x 255 x 23.5 mm | Q15: 2.29 kg | R15: Performance blue | S15: 1 Year | T15: 33999 | U15: 13th generation | V15: up to 4.6 GHz with Intel® Turbo Boost Technology, 12 MB L3 cache, 8 cores, 12 threads | W15: 8Y5V3EA
A16: HP | B16: VICTUS 15-FA1112NIA | C16: Intel® Core™ i5-13420H | D16: NVIDIA® GeForce RTX™ 3050 | E16: 6 GB GDDR6 | F16: 8 GB DDR4-3200 MT/s (1 x 8 GB) Transfer rates up to 3200 MT/s. 1 x 8 GB | G16: 512 GB PCIe® Gen4 NVMe™ M.2 SSD | H16: 15.6″ FHD (1920×1080), IPS, 144 Hz, 250 nits, 45% NTSC, anti-glare | I16: 1920 x 1080 | J16: 144 Hz | K16: DOS | L16: Full-size, backlit, mica silver keyboard with numeric keypad | M16: 4-cell, 70 Wh Li-ion polymer | N16: HP Wide Vision 720p HD camera with temporal noise reduction and integrated dual array digital microphones | O16: 1 USB Type-A 5Gbps signaling rate; 1 USB Type-A 5Gbps signaling rate (HP Sleep and Charge); 1 USB Type-C® 5Gbps signaling rate (DisplayPort™ 1.4, HP Sleep and Charge); 1 HDMI 2.1; 1 RJ-45; 1 AC smart pin; 1 headphone/microphone combo | P16: 255 × 357 × 23.5 mm | Q16: 2.29 kg | R16: Mica silver | S16: 1 Year | T16: 33999 | U16: 13th generation | V16: up to 4.6 GHz with Intel® Turbo Boost Technology, 12 MB L3 cache, 8 cores, 12 threads | W16: 8Y605EA
A17: HP | B17: OMEN Slim 16-an0119nrav | C17: Intel® Core™ Ultra 9 285H | D17: NVIDIA® GeForce RTX™ 5070 | E17: 8 GB GDDR7 | F17: 16 GB DDR5-5600 MT/s (2 x 8 GB) Transfer rates up to 5600 MT/s. 2 x 8 GB | G17: 1 TB PCIe® Gen4 NVMe™ M.2 SSD | H17: 16" diagonal WQXGA display | I17: 2560 x 1600 | J17: 240Hz | K17: Windows11 Home | L17: Full-size, 4-zone RGB backlit, shadow black keyboard with numeric keypad and 26-Key Rollover Anti-Ghosting Key technology | M17: 4-cell, 70 Wh Li-ion polymer | N17: HP True Vision 1080p FHD camera with temporal noise reduction and integrated dual array digital microphones | O17: 1 USB Type-A 10Gbps signaling rate; 2 USB Type-A 5Gbps signaling rate; 1 AC smart pin; 1 HDMI 2.1; 1 headphone/microphone combo; 1 RJ-45; 1 USB Type-C® 10Gbps signaling rate (USB Power Delivery 3.0, DisplayPort™ 1.4, HP Sleep and Charge) | P17: 357 x 268 x 19.8 mm | Q17: 2.42 kg | R17: Shadow black | S17: 1 Year | T17: 106999 | V17: up to 5.4 GHz with Intel® Turbo Boost Technology, 24 MB L3 cache, 16 cores, 16 threads | W17: BM7B9UA
A18: HP | B18: OMEN 16-AP0097NR | C18: AMD Ryzen™ AI 9 365 | D18: NVIDIA® GeForce RTX™ 5070 | E18: 8 GB GDDR7 | F18: 32 GB DDR5-5600 MT/s (2 x 16 GB) | G18: 1 TB PCIe® Gen4 NVMe™ M.2 SSD | H18: 16" diagonal, WQXGA , 60-240 Hz, 3 ms response time, IPS, micro-edge, anti-glare, Low Blue Light, 500 nits, 100% sRGB | I18: 2560 x 1600 | J18: 240Hz | K18: Windows11 Home | L18: Full-size, 4-zone RGB backlit, shadow black keyboard with numeric keypad and 26-Key Rollover Anti-Ghosting Key technology | M18: 6-cell, 83 Wh Li-ion polymer | N18: HP True Vision 1080p FHD camera with temporal noise reduction and integrated dual array digital microphones | O18: 1 USB Type-A 10Gbps signaling rate; 2 USB Type-A 5Gbps signaling rate; 1 AC smart pin; 1 HDMI 2.1; 1 headphone/microphone combo; 1 RJ-45; 1 USB Type-C® 10Gbps signaling rate (USB Power Delivery 3.0, DisplayPort™ 1.4, HP Sleep and Charge)[19,42] | P18: 357 x 268 x 23.8 mm | Q18: 2.44kg | R18: Shadow Black | S18: 1 Year | T18: 104999 | V18: up to 5.0 GHz max boost clock, 24 MB L3 cache, 10 cores, 20 threads
A19: Lenovo | B19: Legion 5 15IRX10 | C19: Intel® Core i9-14900HX | D19: NVIDIA® GeForce RTX™ 5070 | E19: 8GB GDDR7 | F19: 1x 16GB SO-DIMM DDR5-5600 | G19: 1TB SSD M.2 2242 PCIe® 4.0x4 NVMe® | H19: 15.1" WQXGA OLED 1000nits (peak) / 500nits (typical) glossy, 100% DCI-P3, 165Hz, Dolby Vision®, DisplayHDR™ True Black 600 | I19: 2560x1600 | J19: 165 HZ | K19: Windows 11 Home | L19: 24-Zone RGB Backlit, English | M19: 80Wh | N19: 5.0MP with E-shutter | O19: 2x USB-A (USB 5Gbps / USB 3.2 Gen 1) 1x USB-A (USB 5Gbps / USB 3.2 Gen 1), Always On 1x USB-C® (USB 10Gbps / USB 3.2 Gen 2), with USB PD 65-100W and DisplayPort™ 2.1 1x USB-C® (USB 10Gbps / USB 3.2 Gen 2), with DisplayPort™ 1.4 1x HDMI® 2.1, up to 8K/60Hz | P19: 344.9 x 255.35 x 19.95-21.54 mm | Q19: 1.9 kg | R19: Eclipse Black | S19: 1 Year | T19: 107999 | U19: 14th generation | V19: 24C (8P + 16E) / 32T, P-core 2.2 / 5.8GHz, E-core 1.6 / 4.1GHz, 36MB | W19: 83LY0007US
A20: ASUS | B20: ROG Zephyrus G16 GA605KP-AI327W | C20: AMD Ryzen™ AI 7 350 | D20: NVIDIA® GeForce RTX™ 5070 Laptop GPU | E20: 8GB GDDR7 | F20: 32GB LPDDR5X 7500 on board(Actual memory speeds may vary by CPU configuration.) | G20: 1TB PCIe® 4.0 NVMe™ M.2 SSD | H20: 16-inch 2.5K , WQXGA) 16:10 aspect ratio | I20: 2560 x 1600 | J20: 240Hz | K20: Windows 11 Home | M20: 90WHrs, 4S1P, 4-cell Li-ion | N20: 1080P FHD IR Camera for Windows Hello | O20: 1x Type-C USB 4 with support for DisplayPort™ / power delivery (data speed up to 40Gbps) 1x USB 3.2 Gen 2 Type-C with support for DisplayPort™ / power delivery (data speed up to 10Gbps) 2x USB 3.2 Gen 2 Type-A (data speed up to 10Gbps) 1x card reader (SD | P20: 354 x 246 x 14.9 x 16.4 mm | Q20: 1.85 Kg | R20: Gray | S20: 1 year | T20: 105200 | V20: 2.0GHz (24MB Cache, up to 5.0GHz, 8 cores, 16 Threads); AMD XDNA™ NPU up to 50TOPS | W20: 90NR0NC1-M00240
A21: Lenovo | B21: Legion Pro 7 16IAX10H | C21: Intel® Core Ultra 9 275HX | D21: NVIDIA® GeForce RTX™ 5080 | E21: 16GB GDDR7 | F21: 2x 32GB CSODIMM DDR5-6400 | G21: 2x 1TB SSD M.2 2280 PCIe® 4.0x4 NVMe® | H21: 16" WQXGA OLED 500nits (Typical) / 1100nits (Peak) Glossy, 100% DCI-P3, 240Hz, DisplayHDR™ True Black 1000, Dolby Vision®, G-SYNC®, Low Blue Light, High Gaming Performance, Flicker Free | I21: 2560x1600 | J21: 240 HZ | K21: Windows® 11 Pro | L21: Per-key RGB Backlit, English | M21: 99.9Wh | N21: 5.0MP with E-shutter | O21: 2x USB-A (USB 5Gbps / USB 3.2 Gen 1) 1x USB-A (USB 10Gbps / USB 3.2 Gen 2), Always On 1x USB-C® (USB 10Gbps / USB 3.2 Gen 2), with USB PD 65-100W and DisplayPort™ 2.1 1x Thunderbolt™ 4 / USB4® 40Gbps (support data transfer and DisplayPort™ 2.1) 1x HDMI® 2 | P21: 364.38 x 275.94 x 21.9-26.65 mm | Q21: 2.57 kg | R21: Eclipse Black | S21: 1 Year | T21: 205000 | V21: 24C (8P + 16E) / 24T, Max Turbo up to 5.4GHz, 36MB | W21: 83F5006HUS
A22: HP | B22: Victus 16-r1046ne | C22: Intel® Core™ i7-14700HX | D22: NVIDIA® GeForce RTX™ 4050 | E22: 6 GB GDDR6 | F22: 16 GB DDR5-5600 MT/s (2 x 8 GB) Transfer rates up to 5600 MT/s. 2 x 8 GB | G22: 1 TB PCIe® Gen4 NVMe™ M.2 SSD | H22: 16.1″ diagonal, FHD (1920 x 1080), 144 Hz, IPS, micro-edge, anti-glare, 300 nits, 62.5% sRGB | I22: 1920 x 1080 | J22: 144 Hz | K22: DOS | L22: Full-size, backlit, performance blue opaque keyboard with numeric keypad | M22: 4-cell, 70 Wh Li-ion polymer | N22: HP True Vision 1080p FHD camera with temporal noise reduction and integrated dual array digital microphones | O22: 1 USB Type-A 5Gbps signaling rate (HP Sleep and Charge); 1 USB Type-C® 5Gbps signaling rate (USB Power Delivery, DisplayPort™ 1.4, HP Sleep and Charge); 2 USB Type-A 5Gbps signaling rate; 1 HDMI 2.1; 1 RJ-45; 1 AC smart pin; 1 headphone/microphone combo | P22: 369 x 259.4 x 22.9 mm | Q22: 2.33 kg | R22: Performance blue | S22: 1 Year | T22: 53999 | U22: 14th generation | V22: up to 5.5 GHz with Intel® Turbo Boost Technology, 33 MB L3 cache, 20 cores, 28 threads | W22: 9X706EA
A23: ASUS | B23: ROG Strix G16 G614PR-RV161W | C23: AMD Ryzen™ 9 8940HX | D23: NVIDIA® GeForce RTX™ 5070 Ti | E23: 12GB GDDR7 | F23: 16GB DDR5-5200 SO-DIMM | G23: 1TB PCIe® 4.0 NVMe™ M.2 SSD | H23: 16-inch FHD+ 16:10 (1920 x 1200, WUXGA) IPS-level anti-glare display sRGB: 100% Refresh Rate: 165Hz Response Time: 3ms G-Sync | I23: 1920 x 1200 | J23: 165 HZ | K23: Windows 11 Home | L23: Backlit Chiclet Keyboard 4-Zone RGB Touchpad | M23: 90WHrs, 4S1P, 4-cell Li-ion | N23: 1080p FHD camera | O23: 1x 3.5mm Combo Audio Jack 1x HDMI 2.1 FRL 2x USB 3.2 Gen 2 Type-A (data speed up to 10Gbps) 1x Type-C USB 4 with support for DisplayPort™ / power delivery / G-SYNC (data speed up to 40Gbps) 1x Type-C USB 4 with support for DisplayPort™ / G-SYNC (data spee | P23: 354 x 264 x 22.6 x 30.4 mm | Q23: 2.50 Kg | R23: Eclipse Gray | S23: سنه | T23: 109300 | V23: 2.4GHz (80MB Cache, up to 5.3GHz, 16 cores, 32 Threads)
A24: ASUS | B24: ROG Strix G16 G614FP-GR169W | C24: AMD Ryzen 9 9955HX | D24: NVIDIA® GeForce RTX™ 5070 | E24: 8GB GDDR7 | F24: 16GB DDR5-5600 SO-DIMM | G24: 1TB PCIe® 4.0 NVMe™ M.2 SSD | H24: 16-inch FHD+ 16:10 (1920 x 1200, WUXGA) 165Hz, 3ms IPS-level 300nits 100% SRGB | I24: 1920 x 1200 | J24: 165 HZ | K24: Windows® 11 Home | L24: Backlit Chiclet Keyboard 4-Zone RGB | M24: 90WHrs, 4S1P, 4-cell Li-ion | N24: 1080p FHD camera | O24: 1x RJ45 LAN port 1x Type-C USB 4 with support for DisplayPort™ (data speed up to 40Gbps) 1x Type-C USB 4 with support for DisplayPort™ / power delivery (data speed up to 40Gbps) 2x USB 3.2 Gen 2 Type-A (data speed up to 10Gbps) | P24: 354 x 264 x 22.6 ~ 30.4 mm | Q24: 2.50 Kg | R24: Eclipse Gray | S24: 1 Year | T24: 102000 | V24: 2.5GHz (80MB Cache, up to 5.4GHz, 16 cores, 32 Threads
A25: ASUS | B25: TUF Gaming A16 FA608UH-RV007W | C25: AMD Ryzen™ 7 260 | D25: NVIDIA® GeForce RTX™ 5050 | E25: 8GB GDDR7 | F25: 16GB DDR5-5600 SO-DIMM | G25: 512GB PCIe® 4.0 NVMe™ M.2 SSD | H25: 16-inch, FHD+ 16:10 , WUXGA), IPS-level, Anti-glare display, sRGB:100%, Adobe:75.35%, Refresh Rate:165Hz, Response Time:3ms, G-Sync, MUX Switch | I25: 1920 x 1200 | J25: 165 HZ | K25: Windows11 Home | L25: Backlit Chiclet Keyboard 1-Zone RGB Touchpad With Copilot key | M25: 90WHrs, 4S1P, 4-cell Li-ion | N25: 1080P FHD IR Camera for Windows Hello | O25: 1x 3.5mm Combo Audio Jack 1x HDMI 2.1 FRL 2x USB 3.2 Gen 2 Type-A (data speed up to 10Gbps) 1x USB 3.2 Gen 2 Type-C with support for DisplayPort™ / power delivery / G-SYNC (data speed up to 10Gbps) 1x USB 2.0 Type-A (data speed up to 480Mbps) 1x Type-C US | P25: 354 x 269 x 17.9 x 179 mm | Q25: 2.20 Kg | R25: Grey | S25: 1 Year | T25: 56199 | V25: 3.8GHz (24MB Cache, up to 5.1 GHz, 8 cores, 16 Threads); AMD XDNA™ NPU up to 16TOPS AMD Ryzen™ 7 H 260 Processor 3.8GHz (24MB Cache, up to 5.1 GHz, 8 cores, 16 Threads); AMD XDNA™ NPU up to 16TOPS
A26: ASUS | B26: TUF Gaming A14 FA401KH-RG019W | C26: AMD Ryzen™ AI 7 350 | D26: NVIDIA® GeForce RTX™ 5050 | E26: 8GB GDDR7 | F26: 16GB*2 LPDDR5X 7500 on board, Max Capacity | G26: 1TB PCIe® 4.0 NVMe™ M.2 SSD | H26: 14-inch, 2.5K (2560 x 1600, WQXGA) 16:10 aspect ratio, IPS-level, Anti-glare display | I26: 2560 x 1600 | J26: 165 HZ | K26: Windows 11 Home | M26: 73WHrs, 4S1P, 4-cell Li-ion | N26: 1080P FHD IR Camera for Windows Hello | O26: 1x 3.5mm Combo Audio Jack 1x HDMI 2.1 FRL 2x USB 3.2 Gen 2 Type-A (data speed up to 10Gbps) 1x USB 3.2 Gen 2 Type-C with support for DisplayPort™ / G-SYNC (data speed up to 10Gbps) 1x Type-C USB 4 with support for DisplayPort™ / power delivery (data speed | P26: 311 x 227 x 16.9 x 19.9 mm | Q26: 1.46 Kg | R26: Grey | S26: 1 Year | T26: 66999 | V26: 2.0GHz (24MB Cache, up to 5.0GHz, 8 cores, 16 Threads); AMD XDNA™ NPU up to 50TOPS
A27: ASUS | B27: TUF Gaming A14 FA401UU-RG028W | C27: AMD Ryzen 7 8845HS | D27: NVIDIA® GeForce RTX™ 4050 6GB | E27: 6GB GDDR6 | F27: 16GB 8GB*2 LPDDR5X 7500 on board | G27: 512GB PCIe® 4.0 NVMe™ M.2 SSD | H27: 14-inch, 2.5K (2560 x 1600, WQXGA) 16:10 aspect ratio, IPS-level, Anti-glare display, sRGB:100.00%, Refresh Rate:165Hz, G-Sync, MUX Switch + NVIDIA® Advanced Optimus | I27: 2560 x 1600 | J27: 165 HZ | K27: Windows® 11 Home | L27: Backlit Chiclet Keyboard Single Light | M27: 73WHrs, 4S1P, 4-cell Li-ion | N27: 1080P FHD IR Camera for Windows Hello | O27: 1x 3.5mm Combo Audio Jack 1x HDMI 2.1 FRL 2x USB 3.2 Gen 2 Type-A (data speed up to 10Gbps) 1x USB 3.2 Gen 2 Type-C with support for DisplayPort™ (data speed up to 10Gbps) 1x Type-C USB 4 with support for DisplayPort™ / power delivery (data speed up to 40 | P27: 311 x 227 x 16.9 ~ 19.9 mm | Q27: 1.46 Kg | R27: Gray | S27: 1 Year | T27: 48888 | V27: 24MB Cache, up to 5.1 GHz, 8 cores, 16 Threads
A28: MSI | B28: Crosshair 18 HX AI A2XWGKG | C28: Intel Core Ultra 9 275HX | D28: Nvidia GeForce RTX 5070 8GB | E28: 8GB GDDR7 | F28: 32GB | G28: 1TB SSD | H28: 18” QHD+ (2560x1600), 240Hz, IPS-Level | I28: 2560x1600 | J28: 240 HZ | K28: Windows® 11 Home | L28: 24-Zone RGB Gaming Keyboard with Copilot Key | M28: 4-Cell 90 Battery (Whr) | N28: HD type (30fps@720p) 3D Noise Reduction (3DNR) | O28: 1x Thunderbolt™ 4 (DisplayPort™/ Power Delivery 3.0) 3x Type-A USB3.2 Gen1 1x HDMI™ 2.1 (8K @ 60Hz / 4K @ 120Hz) | P28: 404 x 280 x 25.6-29.9 mm | Q28: 3.1 kg | R28: Black | S28: 2 Years | T28: 94999 | W28: 9S7-184111-025
A29: MSI | B29: Vector 17 HX AI A2XWJG | C29: Intel Core Ultra 9 275HX | D29: NVIDIA® GeForce RTX™ 5090 24GB | E29: 24GB GDDR7 | F29: 32GB DDR5-6400 | G29: 1TB SSD | H29: 17” QHD+ (2560x1600), 240Hz, IPS-Level | I29: 2560x1600 | J29: 240 HZ | K29: Windows® 11 Home | L29: 24-Zone RGB Gaming Keyboard with Copilot Key | M29: 4-Cell 90 Battery (Whr) | N29: IR FHD type (30fps@1080p) with HDR 3D Noise Reduction+ (3DNR+) | O29: 2x Thunderbolt™ 5 (DisplayPort™/ Power Delivery 3.1) 2x Type-A USB3.2 Gen2 1x SD Express Card Reader 1x HDMI™ 2.1 (8K @ 60Hz / 4K @ 120Hz) | P29: 380.34 x 297.97 x 22.85-28.75 mm | Q29: 3 kg | R29: Cosmos Gray | S29: 2 years | T29: 228337 | W29: 9S7-17S372-204
A30: MSI | B30: Raider 18 HX AI A2XWJG | C30: Intel Core Ultra 9 285HX | D30: Nvidia GeForce RTX 5090 24GB | E30: 24GB GDDR7 | F30: 64GB DDR5 6400MHz 32GB*2 | G30: 2TB NVMe PCIe Gen5x4 SSD | H30: 18” UHD+, MiniLED, 120Hz | I30: 3840 x 2400 | J30: 120 Hz | K30: Windows® 11 Home | L30: Per-Key RGB Gaming Keyboard by SteelSeries with Copilot Key | M30: 4-Cell 99 Battery (Whr) | N30: IR FHD type (30fps@1080p) with HDR 3D Noise Reduction+ (3DNR+) | O30: 2x Thunderbolt™ 5 (DisplayPort™/ Power Delivery 3.1) 3x Type-A USB3.2 Gen2 1x SD Express Card Reader | P30: 404 x 307.5 x 24-32.05 mm | Q30: 3.6 kg | R30: Core Black | S30: 2 years | T30: 249999
A31: Acer | B31: Aspire 5 A515-57G-59VY | C31: Intel Core i5-1235U | D31: Nvidia GeForce RTX 2050 4GB | F31: 8GB DDR4 SDRAM | G31: 512GB PCIe NVMe SSD | H31: 15.6-inch Full HD (1920×1080) IPS, ComfyView (Matte), 16:9 aspect ratio | I31: 1920x1080 | K31: DOS | L31: Full-size keyboard | M31: 3-cell Li-Ion, 50Wh | N31: HD webcam | O31: 3 × USB Type-A 3.2 Gen 1 1 × USB Type-C 3.2 Gen 1 1 × HDMI 1 × Headphone/Microphone Combo Jack (3.5mm) 1 × RJ-45 (Ethernet Port) | P31: 362 x 237 x 17.9 mm | Q31: 1.8 kg | R31: Gray | S31: 1 Year | T31: 26699 | U31: 12th generation
A32: HP | B32: Victus 15-FA1023NIA | C32: Intel Core i5-13500H | D32: Nvidia GeForce RTX 3050 6GB | E32: 6GB GDDR6 dedicated | F32: 8 GB DDR4-3200 MT/s (1 x 8 GB) | G32: 512 GB PCIe® Gen4 NVMe™ M.2 SSD | H32: 39.6 cm (15.6") diagonal, FHD, 144 Hz, 9 ms response time, IPS, micro-edge, anti-glare, 250 nits, 45% NTSC | I32: 1920 x 1080 | J32: 144 Hz | K32: DOS | L32: Full-size, backlit, performance blue keyboard with numeric keypad | M32: 4-cell, 70 Wh Li-ion polymer | N32: HP Wide Vision 720p HD camera with temporal noise reduction and integrated dual array digital microphones | O32: 1 USB Type-A 5Gbps signaling rate; 1 USB Type-A 5Gbps signaling rate (HP Sleep and Charge); 1 USB Type-C® 5Gbps signaling rate (DisplayPort™ 1.4, HP Sleep and Charge); 1 HDMI 2.1; 1 RJ-45; 1 AC smart pin; 1 headphone/microphone combo | P32: 35.79 x 25.5 x 2.35 cm | Q32: 2.29 kg | R32: Performance blue | S32: 1 Year | T32: 34999 | U32: 13th generation | V32: up to 4.7 GHz with Intel® Turbo Boost Technology, 18 MB L3 cache, 12 cores, 16 threads | W32: 803C1EA
A33: MSI | B33: Thin 15 B2RVE | C33: Intel Core 7 240H | D33: Nvidia GeForce RTX 4050 6GB | E33: 6GB GDDR6 | F33: 16GB 2x 8GB | G33: 512GB M.2 SSD NVMe PCIe Gen4 | H33: 15.6" FHD (1920x1080), 144Hz, IPS-Level | I33: 1920 x 1080 | J33: 144 Hz | K33: DOS | L33: Single Backlit Keyboard (Blue) with Copilot Key | M33: 3-Cell 52.4 Battery (Whr) | N33: HD type (30fps@720p) | O33: 1x Type-C (USB3.2 Gen1 / DisplayPort™) 3x Type-A USB3.2 Gen1 1x HDMI™ (4K @ 30Hz) | P33: 359 x 254 x 21.7 mm | Q33: 1.86 kg | R33: Cosmos Gray | S33: 2 Years | T33: 41999
A34: MSI | B34: Katana 15 HX B14WFK | C34: Intel® Core™ i7-14650HX | D34: NVIDIA® GeForce RTX™ 5060 Laptop GPU | E34: GDDR7 8GB | F34: DDR5 8GB*2 | G34: 512GB NVMe PCIe SSD Gen4x4 w/o DRAM | H34: 15.6" QHD (2560*1440), 165Hz DCI-P3 100% typical | I34: 2560*1440 | K34: DOS | L34: 4-Zone RGB Gaming Keyboard | M34: 4 cell, 75Whr | N34: HD type (30fps@720p) | O34: 1x Type-C (USB3.2 Gen2 / DisplayPort™/ Power Delivery 3.0) 3x Type-A USB3.2 Gen2 1x HDMI™ 2.1 (8K @ 60Hz / 4K @ 120Hz) | P34: 359 x 262 x 25.5 mm | Q34: 2.4 kg | R34: Black | S34: 2 Years | T34: 61999
A35: MSI | B35: Katana 15 HX B14WFK | C35: Intel® Core™ i9-14900HX | D35: NVIDIA® GeForce RTX™ 5060 | E35: 8GB GDDR7 | F35: 16GB 8GB*2 DDR5 | G35: 1TB NVMe PCIe SSD Gen4x4 | H35: 15.6" QHD, 165Hz DCI-P3 100% typical | I35: 2560*1440 | J35: 165 HZ | K35: Windows® 11 Home | L35: 4-Zone RGB Gaming Keyboard with Copilot Key | M35: 4 cell, 75Whr | N35: HD type (30fps@720p) | O35: 1x Type-C (USB3.2 Gen2 / DisplayPort™/ Power Delivery 3.0) 3x Type-A USB3.2 Gen2 1x HDMI™ 2.1 (8K @ 60Hz / 4K @ 120Hz) | P35: 359 x 262 x 25.5 mm | Q35: 2.4 kg | R35: Black | S35: 2 Years | T35: 69999 | U35: 14th generation
A36: Lenovo | B36: LOQ 15ARP9 | C36: AMD Ryzen™ 7 7435HS | D36: NVIDIA® GeForce RTX™ 4050 6GB GDDR6 | E36: 6GB GDDR6 | F36: 12GB SO-DIMM DDR5-4800 | G36: 512GB SSD M.2 2242 PCIe® 4.0x4 NVMe® | H36: 15.6" FHD IPS 300nits Anti-glare, 100% sRGB, 144Hz, G-SYNC® | I36: 1920x1080 | J36: 144 Hz | K36: DOS | L36: White Backlit, Arabic | M36: 60Wh | N36: HD 720p with E-Shutter | O36: 3x USB-A (USB 5Gbps / USB 3.2 Gen 1) 1x USB-C® (USB 10Gbps / USB 3.2 Gen 2), with Lenovo® PD 140W and DisplayPort™ 1.4 1x HDMI® 2.1, up to 8K/60Hz 1x Headphone / microphone combo jack (3.5mm) 1x Ethernet (RJ-45) 1x Power connector | P36: 359.86 x 258.7 x 21.9-23.9 mm | Q36: 2.38 kg | R36: Luna Grey | S36: 1 Year | T36: 39999 | V36: 8C / 16T, 3.1 / 4.5GHz, 4MB L2 / 16MB L3 | W36: 83JC00H2ED
A37: HP | B37: Victus 16-r0053nia | C37: Intel® Core™ i7-13700H | D37: NVIDIA® GeForce RTX™ 3050 | E37: 6 GB GDDR6 | F37: 16 GB DDR5-5200 MT/s | G37: 1 TB PCIe® Gen4 NVMe™ M.2 SSD | H37: 16.1" diagonal, FHD, 144 Hz, IPS, micro-edge, anti-glare, 250 nits, 45% NTSC | I37: 1920 x 1080 | J37: 144 Hz | K37: DOS | L37: Full-size, backlit, performance blue opaque keyboard with numeric keypad | M37: 4-cell, 70 Wh Li-ion polymer | N37: HP True Vision 1080p FHD camera with temporal noise reduction and integrated dual array digital microphones | O37: 1 USB Type-A 5Gbps signaling rate (HP Sleep and Charge); 1 USB Type-C® 5Gbps signaling rate (USB Power Delivery, DisplayPort™ 1.4, HP Sleep and Charge); 2 USB Type-A 5Gbps signaling rate; 1 HDMI 2.1; 1 RJ-45; 1 AC smart pin; 1 headphone/microphone combo | P37: 369 x 259 x 22.9 mm | Q37: 2.31 kg | R37: Performance blue | S37: 1 Year | T37: 42999 | U37: 13th generation | V37: up to 5.0 GHz with Intel® Turbo Boost Technology, 24 MB L3 cache, 14 cores, 20 threads | W37: 81Q11EA
A38: Lenovo | B38: LOQ 15ARP9 | C38: AMD Ryzen 7 7435HS | D38: Nvidia GeForce RTX 4060 8GB | E38: 8GB GDDR6 | F38: 1x 12GB SO-DIMM DDR5-4800 | G38: 512GB SSD M.2 2242 PCIe® 4.0x4 NVMe® | H38: 15.6" FHD IPS 300nits Anti-glare, 100% sRGB, 144Hz, G-SYNC® | I38: 1920 x 1080 | J38: 144 Hz | K38: DOS | L38: White Backlit, Arabic | M38: 60Wh | N38: HD 720p with E-Shutter | O38: 3x USB-A (USB 5Gbps / USB 3.2 Gen 1) 1x USB-C® (USB 10Gbps / USB 3.2 Gen 2), with Lenovo® PD 140W and DisplayPort™ 1.4 1x HDMI® 2.1, up to 8K/60Hz 1x Headphone / microphone combo jack (3.5mm) 1x Ethernet (RJ-45) 1x Power connector | P38: 359.86 x 258.7 x 21.9-23.9 mm | Q38: 2.38 kg | R38: Luna Grey | S38: 1 year | T38: 47777 | V38: (8C / 16T, 3.1 / 4.5GHz, 4MB L2 / 16MB L3) | W38: 83JC00H1ED
A39: Dell | B39: G15 5530 | C39: Intel Core I5-13450HX | D39: Nvidia GeForce RTX 3050 6GB | E39: 6GB GDDR6 | F39: 16GB, 1x16GB, DDR5, 4800MT/s | G39: 512GB, M.2, PCIe NVMe, SSD | H39: 15.6" FHD (1920x1080) 120Hz | I39: 1920 x 1080 | J39: 120 Hz | K39: DOS | L39: Arabic Qwerty 4-Zone RGB Backlit Keyboard with Numeric Keypad and G-Key | M39: 3-Cell Battery, 56WHr | O39: 1 headset (headphone and microphone combo) port 1 RJ45 Ethernet port 3 USB 3.2 Gen 1 ports 1 HDMI 2.1 port 1 USB-C 3.2 Gen 2 port with DisplayPort™ | P39: 357.26 x 274.52 x 26.95 mm | Q39: 2.81 kg | R39: Dark Gray | S39: 3 Years | T39: 37777 | U39: 13th generation | V39: 20 MB cache, 1 0 core, up to 4.60 GHz | X39: 180W AC Adapter
A40: Lenovo | B40: Legion Pro 5 16IRX10 | C40: Intel Core i7-14650HX | D40: Nvidia GeForce RTX 5050 8GB | E40: 8GB GDDR7 | F40: 1x 16GB SO-DIMM DDR5-5600 | G40: 512GB SSD M.2 2242 PCIe® 4.0x4 NVMe® | H40: 16" WQXGA IPS 500nits Anti-glare, 100% DCI-P3, 240Hz, DisplayHDR™ 400, Dolby Vision®, G-SYNC®, Low Blue Light, High Gaming Performance | I40: 2560x1600 | J40: 240 HZ | K40: Windows® 11 Home | L40: 24-Zone RGB Backlit, Arabic | M40: 80Wh | N40: 5.0MP with E-shutter | O40: 2x USB-A (USB 5Gbps / USB 3.2 Gen 1) 1x USB-A (USB 10Gbps / USB 3.2 Gen 2), Always On 1x USB-C® (USB 10Gbps / USB 3.2 Gen 2), with USB PD 65-100W and DisplayPort™ 2.1 1x USB-C® (USB 10Gbps / USB 3.2 Gen 2), with DisplayPort™ 1.4 1x HDMI® 2.1, up to 8K/60H | P40: 364.38 x 268.06 x 21.69-25.95 mm | Q40: 2.4 kg | R40: Eclipse Black | S40: 2 Years | T40: 66666 | U40: 14th generation | V40: 16C (8P + 8E) / 24T, P-core 2.2 / 5.2GHz, E-core 1.6 / 3.7GHz, 30MB | W40: 83NN001SED
...

Sheet Worksheet
A1: Brand | C1: Product Name | F1: Processor | I1: Video Graphics Memorey | J1: 0 | K1: RAM | M1: Hard Drive | P1: Display Resolution | R1: Display Refresh Rate | T1: Operating System | V1: Weight | X1: Warranty | Z1: Price | AA1: Processor Generation
A2: MSI | B2: =IF(OR(UPPER(TRIM(A2))="MSI", UPPER(TRIM(A2))="HP", UPPER(TRIM(A2))="ASUS"), UPPER(TRIM(A2)), PROPER(TRIM(A2))) -> MSI | C2: Titan 18 HX Dragon Edition Norse Myth A2XWJG | D2: =TRIM(CLEAN(SUBSTITUTE(C2,CHAR(160)," "))) -> Titan 18 HX Dragon Edition Norse Myth A2XWJG | E2: {=IFERROR( INDEX(Family_Map!$B$2:$B$35, _xludf.AGGREGATE(14,6,(ROW(Family_Map!$A$2:$A$35)-ROW(Family_Map!$A$2)+1)/(ISNUMBER(SEARCH(Family_Map!$A$2:$A$35,D2))),1) ), "Other")} -> Other | F2: Intel Core Ultra 9 285HX | G2: =TRIM(SUBSTITUTE(SUBSTITUTE(SUBSTITUTE(SUBSTITUTE(SUBSTITUTE(F2,"®",""),"™",""),CHAR(160)," "),_xludf.UNICHAR(8203),"")," "," ")) -> #NAME? | H2: =IF(ISNUMBER(SEARCH("CORE ULTRA 9",G3)),"Intel Core Ultra 9", IF(ISNUMBER(SEARCH("CORE ULTRA 7",G3)),"Intel Core Ultra 7",IF(ISNUMBER(SEARCH("CORE I3",G3)),"Intel Core i3", IF(ISNUMBER(SEARCH("CORE ULTRA 5",G3)),"Intel Core Ultra 5", IF(ISNUMBER(SEARCH("CORE I9",G3)),"Intel Core i9", IF(ISNUMBER(SEARCH("CORE I7",G3)),"Intel Core i7", IF(ISNUMBER(SEARCH("CORE I5",G3)),"Intel Core i5", IF(ISNUMBER(SEARCH("CORE 9",G3)),"Intel Core 9", IF(ISNUMBER(SEARCH("CORE 7",G3)),"Intel Core 7", IF(ISNUMBER(SEARCH("CORE 5",G3)),"Intel Core 5", IF(ISNUMBER(SEARCH("RYZEN AI 9",G3)),"AMD Ryzen AI 9", IF(ISNUMBER(SEARCH("RYZEN AI 7",G3)),"AMD Ryzen AI 7", IF(ISNUMBER(SEARCH("RYZEN 9",G3)),"AMD Ryzen 9", IF(ISNUMBER(SEARCH("RYZEN 7",G3)),"AMD Ryzen 7", IF(ISNUMBER(SEARCH("RYZEN 5",G3)),"AMD Ryzen 5", IF(ISNUMBER(SEARCH("SNAPDRAGON",G3)), IF(ISNUMBER(SEARCH("ELITE",G3)),"Snapdragon X Elite", IF(ISNUMBER(SEARCH("PLUS",G3)),"Snapdragon X Plus","Snapdragon")), "Other")))))))))))))))) -> Other | I2: 24GB GDDR7 | J2: =IFERROR( LEFT( TRIM(MID(I2, MIN(FIND({0,1,2,3,4,5,6,7,8,9}, I2&"0123456789")), 100)), FIND("G", UPPER(TRIM(MID(I2, MIN(FIND({0,1,2,3,4,5,6,7,8,9}, I2&"0123456789")), 100)))) ) & "B", "" ) -> 24GB | K2: 96GB DDR5 6400MHz 48GB*2 | L2: =IFERROR( VALUE(SUBSTITUTE(SUBSTITUTE(LEFT(UPPER(TRIM(K2)),FIND("GB",UPPER(K2)&"GB")+1),"GB","")," ","")), IFERROR( VALUE(SUBSTITUTE(SUBSTITUTE(MID(UPPER(K2),FIND("GB",UPPER(K2)&"GB")-3,3),"GB","")," ","")) * IF( OR( ISNUMBER(SEARCH("2X",UPPER(K2))), ISNUMBER(SEARCH("X 2",UPPER(K2))), ISNUMBER(SEARCH("*2",UPPER(K2))), ISNUMBER(SEARCH("2*",UPPER(K2))), ISNUMBER(SEARCH("(2 X",UPPER(K2))) ), 2,1), "") ) -> 96 | M2: 6TB, 2TB NVMe PCIe Gen5x4 SSD w/o DRAM + 2TB NVMe PCIe Gen4x4 SSD x2 | N2: =IFERROR( LEFT( TRIM(MID(M2, MIN(FIND({0,1,2,3,4,5,6,7,8,9}, M2&"0123456789")), 100)), FIND("B", UPPER(TRIM(MID(M2, MIN(FIND({0,1,2,3,4,5,6,7,8,9}, M2&"0123456789")), 100)))) ), "" ) -> 6TB | O2: =IFERROR( IF(RIGHT(TRIM(N2),2)="TB", VALUE(LEFT(TRIM(N2),LEN(TRIM(N2))-2))*1024 & "GB", TRIM(N2) ), "") -> 6144GB | P2: 3840x2400 | Q2: =IFERROR( SUBSTITUTE(SUBSTITUTE(SUBSTITUTE(SUBSTITUTE(SUBSTITUTE(SUBSTITUTE( TRIM(P2), "*","x"),"×","x"),"X","x")," x ","x"),"x ","x")," x","x"), "") -> 3840x2400 | R2: 120 Hz | S2: =IFERROR( TRIM(LEFT(TRIM(R2), FIND(UPPER("H"), UPPER(TRIM(R2)))-1)) & "Hz", "") -> 120Hz | T2: Windows® 11 Home | U2: =IFERROR( IF(AND(ISNUMBER(SEARCH("11",T2)),ISNUMBER(SEARCH("pro",T2))),"Windows 11 Pro", IF(AND(ISNUMBER(SEARCH("10",T2)),ISNUMBER(SEARCH("pro",T2))),"Windows 10 Pro", IF(ISNUMBER(SEARCH("11",T2)),"Windows 11 Home", IF(ISNUMBER(SEARCH("10",T2)),"Windows 10 Home", IF(OR(ISNUMBER(SEARCH("dos",T2)),ISNUMBER(SEARCH("DOS",T2))),"DOS", "Unknown"))))), "Unknown") -> Windows 11 Home | V2: 3.6 kg | W2: =IFERROR( IF(ISNUMBER(SEARCH(" g",SUBSTITUTE(V2,"gk","kg"))), ROUND(VALUE(TRIM(LEFT(SUBSTITUTE(V2,"gk","kg"),FIND(" ",SUBSTITUTE(V2,"gk","kg"))-1)))/1000,2) & " kg", IF(ISNUMBER(SEARCH("lb",V2)), ROUND(VALUE(TRIM(LEFT(V2,FIND(" ",V2)-1)))*0.453592,2) & " kg", ROUND(VALUE(TRIM(SUBSTITUTE(SUBSTITUTE(SUBSTITUTE(SUBSTITUTE(SUBSTITUTE(V2,"kg",""),"Kg",""),"KG",""),"gk",""),"g",""))),2) & " kg" )), "") -> 3.6 kg | X2: 2 Year | Y2: =IFERROR( IF(ISNUMBER(SEARCH("3",X2)), "3 Years", IF(ISNUMBER(SEARCH("2",X2)), "2 Years", IF(ISNUMBER(SEARCH("1",X2)), "1 Year", "Check Manually"))), "") -> 2 Years | Z2: 320000 | AA2: Unknown
A3: MSI | B3: =IF(OR(UPPER(TRIM(A3))="MSI", UPPER(TRIM(A3))="HP", UPPER(TRIM(A3))="ASUS"), UPPER(TRIM(A3)), PROPER(TRIM(A3))) -> MSI | C3: Katana 15 HX 14XWGK | D3: =TRIM(CLEAN(SUBSTITUTE(C3,CHAR(160)," "))) -> Katana 15 HX 14XWGK | E3: {=IFERROR( INDEX(Family_Map!$B$2:$B$35, _xludf.AGGREGATE(14,6,(ROW(Family_Map!$A$2:$A$35)-ROW(Family_Map!$A$2)+1)/(ISNUMBER(SEARCH(Family_Map!$A$2:$A$35,D3))),1) ), "Other")} -> Other | F3: Intel Core i9-I4900HX | G3: =TRIM(SUBSTITUTE(SUBSTITUTE(SUBSTITUTE(SUBSTITUTE(SUBSTITUTE(F3,"®",""),"™",""),CHAR(160)," "),_xludf.UNICHAR(8203),"")," "," ")) -> #NAME? | H3: =IF(ISNUMBER(SEARCH("CORE ULTRA 9",G3)),"Intel Core Ultra 9", IF(ISNUMBER(SEARCH("CORE ULTRA 7",G3)),"Intel Core Ultra 7",IF(ISNUMBER(SEARCH("CORE I3",G3)),"Intel Core i3", IF(ISNUMBER(SEARCH("CORE ULTRA 5",G3)),"Intel Core Ultra 5", IF(ISNUMBER(SEARCH("CORE I9",G3)),"Intel Core i9", IF(ISNUMBER(SEARCH("CORE I7",G3)),"Intel Core i7", IF(ISNUMBER(SEARCH("CORE I5",G3)),"Intel Core i5", IF(ISNUMBER(SEARCH("CORE 9",G3)),"Intel Core 9", IF(ISNUMBER(SEARCH("CORE 7",G3)),"Intel Core 7", IF(ISNUMBER(SEARCH("CORE 5",G3)),"Intel Core 5", IF(ISNUMBER(SEARCH("RYZEN AI 9",G3)),"AMD Ryzen AI 9", IF(ISNUMBER(SEARCH("RYZEN AI 7",G3)),"AMD Ryzen AI 7", IF(ISNUMBER(SEARCH("RYZEN 9",G3)),"AMD Ryzen 9", IF(ISNUMBER(SEARCH("RYZEN 7",G3)),"AMD Ryzen 7", IF(ISNUMBER(SEARCH("RYZEN 5",G3)),"AMD Ryzen 5", IF(ISNUMBER(SEARCH("SNAPDRAGON",G3)), IF(ISNUMBER(SEARCH("ELITE",G3)),"Snapdragon X Elite", IF(ISNUMBER(SEARCH("PLUS",G3)),"Snapdragon X Plus","Snapdragon")), "Other")))))))))))))))) -> Other | I3: 8GB GDDR7 | J3: =IFERROR( LEFT( TRIM(MID(I3, MIN(FIND({0,1,2,3,4,5,6,7,8,9}, I3&"0123456789")), 100)), FIND("G", UPPER(TRIM(MID(I3, MIN(FIND({0,1,2,3,4,5,6,7,8,9}, I3&"0123456789")), 100)))) ) & "B", "" ) -> 8GB | K3: 16GB DDR5 8GB*2 | L3: =IFERROR( VALUE(SUBSTITUTE(SUBSTITUTE(LEFT(UPPER(TRIM(K3)),FIND("GB",UPPER(K3)&"GB")+1),"GB","")," ","")), IFERROR( VALUE(SUBSTITUTE(SUBSTITUTE(MID(UPPER(K3),FIND("GB",UPPER(K3)&"GB")-3,3),"GB","")," ","")) * IF( OR( ISNUMBER(SEARCH("2X",UPPER(K3))), ISNUMBER(SEARCH("X 2",UPPER(K3))), ISNUMBER(SEARCH("*2",UPPER(K3))), ISNUMBER(SEARCH("2*",UPPER(K3))), ISNUMBER(SEARCH("(2 X",UPPER(K3))) ), 2,1), "") ) -> 16 | M3: 1TB NVMe PCIe SSD Gen4x4 | N3: =IFERROR( LEFT( TRIM(MID(M3, MIN(FIND({0,1,2,3,4,5,6,7,8,9}, M3&"0123456789")), 100)), FIND("B", UPPER(TRIM(MID(M3, MIN(FIND({0,1,2,3,4,5,6,7,8,9}, M3&"0123456789")), 100)))) ), "" ) -> 1TB | O3: =IFERROR( IF(RIGHT(TRIM(N3),2)="TB", VALUE(LEFT(TRIM(N3),LEN(TRIM(N3))-2))*1024 & "GB", TRIM(N3) ), "") -> 1024GB | P3: 2560*1440 | Q3: =IFERROR( SUBSTITUTE(SUBSTITUTE(SUBSTITUTE(SUBSTITUTE(SUBSTITUTE(SUBSTITUTE( TRIM(P3), "*","x"),"×","x"),"X","x")," x ","x"),"x ","x")," x","x"), "") -> 2560x1440 | R3: 165 HZ | S3: =IFERROR( TRIM(LEFT(TRIM(R3), FIND(UPPER("H"), UPPER(TRIM(R3)))-1)) & "Hz", "") -> 165Hz | T3: Windows® 11 Home | U3: =IFERROR( IF(AND(ISNUMBER(SEARCH("11",T3)),ISNUMBER(SEARCH("pro",T3))),"Windows 11 Pro", IF(AND(ISNUMBER(SEARCH("10",T3)),ISNUMBER(SEARCH("pro",T3))),"Windows 10 Pro", IF(ISNUMBER(SEARCH("11",T3)),"Windows 11 Home", IF(ISNUMBER(SEARCH("10",T3)),"Windows 10 Home", IF(OR(ISNUMBER(SEARCH("dos",T3)),ISNUMBER(SEARCH("DOS",T3))),"DOS", "Unknown"))))), "Unknown") -> Windows 11 Home | V3: 2.4 kg | W3: =IFERROR( IF(ISNUMBER(SEARCH(" g",SUBSTITUTE(V3,"gk","kg"))), ROUND(VALUE(TRIM(LEFT(SUBSTITUTE(V3,"gk","kg"),FIND(" ",SUBSTITUTE(V3,"gk","kg"))-1)))/1000,2) & " kg", IF(ISNUMBER(SEARCH("lb",V3)), ROUND(VALUE(TRIM(LEFT(V3,FIND(" ",V3)-1)))*0.453592,2) & " kg", ROUND(VALUE(TRIM(SUBSTITUTE(SUBSTITUTE(SUBSTITUTE(SUBSTITUTE(SUBSTITUTE(V3,"kg",""),"Kg",""),"KG",""),"gk",""),"g",""))),2) & " kg" )), "") -> 2.4 kg | X3: 2 Year | Y3: =IFERROR( IF(ISNUMBER(SEARCH("3",X3)), "3 Years", IF(ISNUMBER(SEARCH("2",X3)), "2 Years", IF(ISNUMBER(SEARCH("1",X3)), "1 Year", "Check Manually"))), "") -> 2 Years | Z3: 79999 | AA3: 14th generation
A4: Acer | B4: =IF(OR(UPPER(TRIM(A4))="MSI", UPPER(TRIM(A4))="HP", UPPER(TRIM(A4))="ASUS"), UPPER(TRIM(A4)), PROPER(TRIM(A4))) -> Acer | C4: NITRO V15-ANV15-51-51H9 | D4: =TRIM(CLEAN(SUBSTITUTE(C4,CHAR(160)," "))) -> NITRO V15-ANV15-51-51H9 | E4: {=IFERROR( INDEX(Family_Map!$B$2:$B$35, _xludf.AGGREGATE(14,6,(ROW(Family_Map!$A$2:$A$35)-ROW(Family_Map!$A$2)+1)/(ISNUMBER(SEARCH(Family_Map!$A$2:$A$35,D4))),1) ), "Other")} -> Other | F4: Intel Core I5-13420H | G4: =TRIM(SUBSTITUTE(SUBSTITUTE(SUBSTITUTE(SUBSTITUTE(SUBSTITUTE(F4,"®",""),"™",""),CHAR(160)," "),_xludf.UNICHAR(8203),"")," "," ")) -> #NAME? | H4: =IF(ISNUMBER(SEARCH("CORE ULTRA 9",G4)),"Intel Core Ultra 9", IF(ISNUMBER(SEARCH("CORE ULTRA 7",G4)),"Intel Core Ultra 7",IF(ISNUMBER(SEARCH("CORE I3",G4)),"Intel Core i3", IF(ISNUMBER(SEARCH("CORE ULTRA 5",G4)),"Intel Core Ultra 5", IF(ISNUMBER(SEARCH("CORE I9",G4)),"Intel Core i9", IF(ISNUMBER(SEARCH("CORE I7",G4)),"Intel Core i7", IF(ISNUMBER(SEARCH("CORE I5",G4)),"Intel Core i5", IF(ISNUMBER(SEARCH("CORE 9",G4)),"Intel Core 9", IF(ISNUMBER(SEARCH("CORE 7",G4)),"Intel Core 7", IF(ISNUMBER(SEARCH("CORE 5",G4)),"Intel Core 5", IF(ISNUMBER(SEARCH("RYZEN AI 9",G4)),"AMD Ryzen AI 9", IF(ISNUMBER(SEARCH("RYZEN AI 7",G4)),"AMD Ryzen AI 7", IF(ISNUMBER(SEARCH("RYZEN 9",G4)),"AMD Ryzen 9", IF(ISNUMBER(SEARCH("RYZEN 7",G4)),"AMD Ryzen 7", IF(ISNUMBER(SEARCH("RYZEN 5",G4)),"AMD Ryzen 5", IF(ISNUMBER(SEARCH("SNAPDRAGON",G4)), IF(ISNUMBER(SEARCH("ELITE",G4)),"Snapdragon X Elite", IF(ISNUMBER(SEARCH("PLUS",G4)),"Snapdragon X Plus","Snapdragon")), "Other")))))))))))))))) -> Other | I4: 6GB GDDR6 | J4: =IFERROR( LEFT( TRIM(MID(I4, MIN(FIND({0,1,2,3,4,5,6,7,8,9}, I4&"0123456789")), 100)), FIND("G", UPPER(TRIM(MID(I4, MIN(FIND({0,1,2,3,4,5,6,7,8,9}, I4&"0123456789")), 100)))) ) & "B", "" ) -> 6GB | K4: 8 GB DDR5-SDRAM | L4: =IFERROR( VALUE(SUBSTITUTE(SUBSTITUTE(LEFT(UPPER(TRIM(K4)),FIND("GB",UPPER(K4)&"GB")+1),"GB","")," ","")), IFERROR( VALUE(SUBSTITUTE(SUBSTITUTE(MID(UPPER(K4),FIND("GB",UPPER(K4)&"GB")-3,3),"GB","")," ","")) * IF( OR( ISNUMBER(SEARCH("2X",UPPER(K4))), ISNUMBER(SEARCH("X 2",UPPER(K4))), ISNUMBER(SEARCH("*2",UPPER(K4))), ISNUMBER(SEARCH("2*",UPPER(K4))), ISNUMBER(SEARCH("(2 X",UPPER(K4))) ), 2,1), "") ) -> 8 | M4: 512 GB SSD | N4: =IFERROR( LEFT( TRIM(MID(M4, MIN(FIND({0,1,2,3,4,5,6,7,8,9}, M4&"0123456789")), 100)), FIND("B", UPPER(TRIM(MID(M4, MIN(FIND({0,1,2,3,4,5,6,7,8,9}, M4&"0123456789")), 100)))) ), "" ) -> 512 GB | O4: =IFERROR( IF(RIGHT(TRIM(N4),2)="TB", VALUE(LEFT(TRIM(N4),LEN(TRIM(N4))-2))*1024 & "GB", TRIM(N4) ), "") -> 512 GB | P4: 1920x1080 | Q4: =IFERROR( SUBSTITUTE(SUBSTITUTE(SUBSTITUTE(SUBSTITUTE(SUBSTITUTE(SUBSTITUTE( TRIM(P4), "*","x"),"×","x"),"X","x")," x ","x"),"x ","x")," x","x"), "") -> 1920x1080 | R4: 144 Hz | S4: =IFERROR( TRIM(LEFT(TRIM(R4), FIND(UPPER("H"), UPPER(TRIM(R4)))-1)) & "Hz", "") -> 144Hz | T4: Windows® 11 Home | U4: =IFERROR( IF(AND(ISNUMBER(SEARCH("11",T4)),ISNUMBER(SEARCH("pro",T4))),"Windows 11 Pro", IF(AND(ISNUMBER(SEARCH("10",T4)),ISNUMBER(SEARCH("pro",T4))),"Windows 10 Pro", IF(ISNUMBER(SEARCH("11",T4)),"Windows 11 Home", IF(ISNUMBER(SEARCH("10",T4)),"Windows 10 Home", IF(OR(ISNUMBER(SEARCH("dos",T4)),ISNUMBER(SEARCH("DOS",T4))),"DOS", "Unknown"))))), "Unknown") -> Windows 11 Home | W4: =IFERROR( IF(ISNUMBER(SEARCH(" g",SUBSTITUTE(V4,"gk","kg"))), ROUND(VALUE(TRIM(LEFT(SUBSTITUTE(V4,"gk","kg"),FIND(" ",SUBSTITUTE(V4,"gk","kg"))-1)))/1000,2) & " kg", IF(ISNUMBER(SEARCH("lb",V4)), ROUND(VALUE(TRIM(LEFT(V4,FIND(" ",V4)-1)))*0.453592,2) & " kg", ROUND(VALUE(TRIM(SUBSTITUTE(SUBSTITUTE(SUBSTITUTE(SUBSTITUTE(SUBSTITUTE(V4,"kg",""),"Kg",""),"KG",""),"gk",""),"g",""))),2) & " kg" )), "") | X4: 1 Year | Y4: =IFERROR( IF(ISNUMBER(SEARCH("3",X4)), "3 Years", IF(ISNUMBER(SEARCH("2",X4)), "2 Years", IF(ISNUMBER(SEARCH("1",X4)), "1 Year", "Check Manually"))), "") -> 1 Year | Z4: 39999 | AA4: 13th generation
A5: Dell | B5: =IF(OR(UPPER(TRIM(A5))="MSI", UPPER(TRIM(A5))="HP", UPPER(TRIM(A5))="ASUS"), UPPER(TRIM(A5)), PROPER(TRIM(A5))) -> Dell | C5: Alienware 16 Aurora AC16250 | D5: =TRIM(CLEAN(SUBSTITUTE(C5,CHAR(160)," "))) -> Alienware 16 Aurora AC16250 | E5: {=IFERROR( INDEX(Family_Map!$B$2:$B$35, _xludf.AGGREGATE(14,6,(ROW(Family_Map!$A$2:$A$35)-ROW(Family_Map!$A$2)+1)/(ISNUMBER(SEARCH(Family_Map!$A$2:$A$35,D5))),1) ), "Other")} -> Other | F5: Intel Core 7 240H | G5: =TRIM(SUBSTITUTE(SUBSTITUTE(SUBSTITUTE(SUBSTITUTE(SUBSTITUTE(F5,"®",""),"™",""),CHAR(160)," "),_xludf.UNICHAR(8203),"")," "," ")) -> #NAME? | H5: =IF(ISNUMBER(SEARCH("CORE ULTRA 9",G5)),"Intel Core Ultra 9", IF(ISNUMBER(SEARCH("CORE ULTRA 7",G5)),"Intel Core Ultra 7",IF(ISNUMBER(SEARCH("CORE I3",G5)),"Intel Core i3", IF(ISNUMBER(SEARCH("CORE ULTRA 5",G5)),"Intel Core Ultra 5", IF(ISNUMBER(SEARCH("CORE I9",G5)),"Intel Core i9", IF(ISNUMBER(SEARCH("CORE I7",G5)),"Intel Core i7", IF(ISNUMBER(SEARCH("CORE I5",G5)),"Intel Core i5", IF(ISNUMBER(SEARCH("CORE 9",G5)),"Intel Core 9", IF(ISNUMBER(SEARCH("CORE 7",G5)),"Intel Core 7", IF(ISNUMBER(SEARCH("CORE 5",G5)),"Intel Core 5", IF(ISNUMBER(SEARCH("RYZEN AI 9",G5)),"AMD Ryzen AI 9", IF(ISNUMBER(SEARCH("RYZEN AI 7",G5)),"AMD Ryzen AI 7", IF(ISNUMBER(SEARCH("RYZEN 9",G5)),"AMD Ryzen 9", IF(ISNUMBER(SEARCH("RYZEN 7",G5)),"AMD Ryzen 7", IF(ISNUMBER(SEARCH("RYZEN 5",G5)),"AMD Ryzen 5", IF(ISNUMBER(SEARCH("SNAPDRAGON",G5)), IF(ISNUMBER(SEARCH("ELITE",G5)),"Snapdragon X Elite", IF(ISNUMBER(SEARCH("PLUS",G5)),"Snapdragon X Plus","Snapdragon")), "Other")))))))))))))))) -> Other | I5: 8 GB GDDR7 | J5: =IFERROR( LEFT( TRIM(MID(I5, MIN(FIND({0,1,2,3,4,5,6,7,8,9}, I5&"0123456789")), 100)), FIND("G", UPPER(TRIM(MID(I5, MIN(FIND({0,1,2,3,4,5,6,7,8,9}, I5&"0123456789")), 100)))) ) & "B", "" ) -> 8 GB | K5: 16GB, 2x8GB, DDR5, 5600 MT/s ( 5200 MT/s with Intel Core 5 CP U) | L5: =IFERROR( VALUE(SUBSTITUTE(SUBSTITUTE(LEFT(UPPER(TRIM(K5)),FIND("GB",UPPER(K5)&"GB")+1),"GB","")," ","")), IFERROR( VALUE(SUBSTITUTE(SUBSTITUTE(MID(UPPER(K5),FIND("GB",UPPER(K5)&"GB")-3,3),"GB","")," ","")) * IF( OR( ISNUMBER(SEARCH("2X",UPPER(K5))), ISNUMBER(SEARCH("X 2",UPPER(K5))), ISNUMBER(SEARCH("*2",UPPER(K5))), ISNUMBER(SEARCH("2*",UPPER(K5))), ISNUMBER(SEARCH("(2 X",UPPER(K5))) ), 2,1), "") ) -> 16 | M5: 512GB M.2 PCIe NVMe SSD | N5: =IFERROR( LEFT( TRIM(MID(M5, MIN(FIND({0,1,2,3,4,5,6,7,8,9}, M5&"0123456789")), 100)), FIND("B", UPPER(TRIM(MID(M5, MIN(FIND({0,1,2,3,4,5,6,7,8,9}, M5&"0123456789")), 100)))) ), "" ) -> 512GB | O5: =IFERROR( IF(RIGHT(TRIM(N5),2)="TB", VALUE(LEFT(TRIM(N5),LEN(TRIM(N5))-2))*1024 & "GB", TRIM(N5) ), "") -> 512GB | P5: 2560 x 1600 | Q5: =IFERROR( SUBSTITUTE(SUBSTITUTE(SUBSTITUTE(SUBSTITUTE(SUBSTITUTE(SUBSTITUTE( TRIM(P5), "*","x"),"×","x"),"X","x")," x ","x"),"x ","x")," x","x"), "") -> 2560x1600 | R5: 120 Hz | S5: =IFERROR( TRIM(LEFT(TRIM(R5), FIND(UPPER("H"), UPPER(TRIM(R5)))-1)) & "Hz", "") -> 120Hz | T5: Windows 11 Home | U5: =IFERROR( IF(AND(ISNUMBER(SEARCH("11",T5)),ISNUMBER(SEARCH("pro",T5))),"Windows 11 Pro", IF(AND(ISNUMBER(SEARCH("10",T5)),ISNUMBER(SEARCH("pro",T5))),"Windows 10 Pro", IF(ISNUMBER(SEARCH("11",T5)),"Windows 11 Home", IF(ISNUMBER(SEARCH("10",T5)),"Windows 10 Home", IF(OR(ISNUMBER(SEARCH("dos",T5)),ISNUMBER(SEARCH("DOS",T5))),"DOS", "Unknown"))))), "Unknown") -> Windows 11 Home | V5: 2.49 kg | W5: =IFERROR( IF(ISNUMBER(SEARCH(" g",SUBSTITUTE(V5,"gk","kg"))), ROUND(VALUE(TRIM(LEFT(SUBSTITUTE(V5,"gk","kg"),FIND(" ",SUBSTITUTE(V5,"gk","kg"))-1)))/1000,2) & " kg", IF(ISNUMBER(SEARCH("lb",V5)), ROUND(VALUE(TRIM(LEFT(V5,FIND(" ",V5)-1)))*0.453592,2) & " kg", ROUND(VALUE(TRIM(SUBSTITUTE(SUBSTITUTE(SUBSTITUTE(SUBSTITUTE(SUBSTITUTE(V5,"kg",""),"Kg",""),"KG",""),"gk",""),"g",""))),2) & " kg" )), "") -> 2.49 kg | X5: 1 Year | Y5: =IFERROR( IF(ISNUMBER(SEARCH("3",X5)), "3 Years", IF(ISNUMBER(SEARCH("2",X5)), "2 Years", IF(ISNUMBER(SEARCH("1",X5)), "1 Year", "Check Manually"))), "") -> 1 Year | Z5: 57999 | AA5: Unknown
A6: Dell | B6: =IF(OR(UPPER(TRIM(A6))="MSI", UPPER(TRIM(A6))="HP", UPPER(TRIM(A6))="ASUS"), UPPER(TRIM(A6)), PROPER(TRIM(A6))) -> Dell | C6: Alienware 16 Aurora AC16250 | D6: =TRIM(CLEAN(SUBSTITUTE(C6,CHAR(160)," "))) -> Alienware 16 Aurora AC16250 | E6: {=IFERROR( INDEX(Family_Map!$B$2:$B$35, _xludf.AGGREGATE(14,6,(ROW(Family_Map!$A$2:$A$35)-ROW(Family_Map!$A$2)+1)/(ISNUMBER(SEARCH(Family_Map!$A$2:$A$35,D6))),1) ), "Other")} -> Other | F6: Intel Core 9 270H | G6: =TRIM(SUBSTITUTE(SUBSTITUTE(SUBSTITUTE(SUBSTITUTE(SUBSTITUTE(F6,"®",""),"™",""),CHAR(160)," "),_xludf.UNICHAR(8203),"")," "," ")) -> #NAME? | H6: =IF(ISNUMBER(SEARCH("CORE ULTRA 9",G6)),"Intel Core Ultra 9", IF(ISNUMBER(SEARCH("CORE ULTRA 7",G6)),"Intel Core Ultra 7",IF(ISNUMBER(SEARCH("CORE I3",G6)),"Intel Core i3", IF(ISNUMBER(SEARCH("CORE ULTRA 5",G6)),"Intel Core Ultra 5", IF(ISNUMBER(SEARCH("CORE I9",G6)),"Intel Core i9", IF(ISNUMBER(SEARCH("CORE I7",G6)),"Intel Core i7", IF(ISNUMBER(SEARCH("CORE I5",G6)),"Intel Core i5", IF(ISNUMBER(SEARCH("CORE 9",G6)),"Intel Core 9", IF(ISNUMBER(SEARCH("CORE 7",G6)),"Intel Core 7", IF(ISNUMBER(SEARCH("CORE 5",G6)),"Intel Core 5", IF(ISNUMBER(SEARCH("RYZEN AI 9",G6)),"AMD Ryzen AI 9", IF(ISNUMBER(SEARCH("RYZEN AI 7",G6)),"AMD Ryzen AI 7", IF(ISNUMBER(SEARCH("RYZEN 9",G6)),"AMD Ryzen 9", IF(ISNUMBER(SEARCH("RYZEN 7",G6)),"AMD Ryzen 7", IF(ISNUMBER(SEARCH("RYZEN 5",G6)),"AMD Ryzen 5", IF(ISNUMBER(SEARCH("SNAPDRAGON",G6)), IF(ISNUMBER(SEARCH("ELITE",G6)),"Snapdragon X Elite", IF(ISNUMBER(SEARCH("PLUS",G6)),"Snapdragon X Plus","Snapdragon")), "Other")))))))))))))))) -> Other | I6: 8GB GDDR7 | J6: =IFERROR( LEFT( TRIM(MID(I6, MIN(FIND({0,1,2,3,4,5,6,7,8,9}, I6&"0123456789")), 100)), FIND("G", UPPER(TRIM(MID(I6, MIN(FIND({0,1,2,3,4,5,6,7,8,9}, I6&"0123456789")), 100)))) ) & "B", "" ) -> 8GB | K6: 16GB, 2x8GB, DDR5, 5600 MT/s | L6: =IFERROR( VALUE(SUBSTITUTE(SUBSTITUTE(LEFT(UPPER(TRIM(K6)),FIND("GB",UPPER(K6)&"GB")+1),"GB","")," ","")), IFERROR( VALUE(SUBSTITUTE(SUBSTITUTE(MID(UPPER(K6),FIND("GB",UPPER(K6)&"GB")-3,3),"GB","")," ","")) * IF( OR( ISNUMBER(SEARCH("2X",UPPER(K6))), ISNUMBER(SEARCH("X 2",UPPER(K6))), ISNUMBER(SEARCH("*2",UPPER(K6))), ISNUMBER(SEARCH("2*",UPPER(K6))), ISNUMBER(SEARCH("(2 X",UPPER(K6))) ), 2,1), "") ) -> 16 | M6: 1TB M.2 PCIe NVMe SSD | N6: =IFERROR( LEFT( TRIM(MID(M6, MIN(FIND({0,1,2,3,4,5,6,7,8,9}, M6&"0123456789")), 100)), FIND("B", UPPER(TRIM(MID(M6, MIN(FIND({0,1,2,3,4,5,6,7,8,9}, M6&"0123456789")), 100)))) ), "" ) -> 1TB | O6: =IFERROR( IF(RIGHT(TRIM(N6),2)="TB", VALUE(LEFT(TRIM(N6),LEN(TRIM(N6))-2))*1024 & "GB", TRIM(N6) ), "") -> 1024GB | P6: 2560 x 1600 | Q6: =IFERROR( SUBSTITUTE(SUBSTITUTE(SUBSTITUTE(SUBSTITUTE(SUBSTITUTE(SUBSTITUTE( TRIM(P6), "*","x"),"×","x"),"X","x")," x ","x"),"x ","x")," x","x"), "") -> 2560x1600 | R6: 120 Hz | S6: =IFERROR( TRIM(LEFT(TRIM(R6), FIND(UPPER("H"), UPPER(TRIM(R6)))-1)) & "Hz", "") -> 120Hz | T6: DOS | U6: =IFERROR( IF(AND(ISNUMBER(SEARCH("11",T6)),ISNUMBER(SEARCH("pro",T6))),"Windows 11 Pro", IF(AND(ISNUMBER(SEARCH("10",T6)),ISNUMBER(SEARCH("pro",T6))),"Windows 10 Pro", IF(ISNUMBER(SEARCH("11",T6)),"Windows 11 Home", IF(ISNUMBER(SEARCH("10",T6)),"Windows 10 Home", IF(OR(ISNUMBER(SEARCH("dos",T6)),ISNUMBER(SEARCH("DOS",T6))),"DOS", "Unknown"))))), "Unknown") -> DOS | V6: 2.49 kg | W6: =IFERROR( IF(ISNUMBER(SEARCH(" g",SUBSTITUTE(V6,"gk","kg"))), ROUND(VALUE(TRIM(LEFT(SUBSTITUTE(V6,"gk","kg"),FIND(" ",SUBSTITUTE(V6,"gk","kg"))-1)))/1000,2) & " kg", IF(ISNUMBER(SEARCH("lb",V6)), ROUND(VALUE(TRIM(LEFT(V6,FIND(" ",V6)-1)))*0.453592,2) & " kg", ROUND(VALUE(TRIM(SUBSTITUTE(SUBSTITUTE(SUBSTITUTE(SUBSTITUTE(SUBSTITUTE(V6,"kg",""),"Kg",""),"KG",""),"gk",""),"g",""))),2) & " kg" )), "") -> 2.49 kg | X6: 1 Year | Y6: =IFERROR( IF(ISNUMBER(SEARCH("3",X6)), "3 Years", IF(ISNUMBER(SEARCH("2",X6)), "2 Years", IF(ISNUMBER(SEARCH("1",X6)), "1 Year", "Check Manually"))), "") -> 1 Year | Z6: 89999 | AA6: Unknown
A7: Dell | B7: =IF(OR(UPPER(TRIM(A7))="MSI", UPPER(TRIM(A7))="HP", UPPER(TRIM(A7))="ASUS"), UPPER(TRIM(A7)), PROPER(TRIM(A7))) -> Dell | C7: Alienware 16 Aurora AC16250 | D7: =TRIM(CLEAN(SUBSTITUTE(C7,CHAR(160)," "))) -> Alienware 16 Aurora AC16250 | E7: {=IFERROR( INDEX(Family_Map!$B$2:$B$35, _xludf.AGGREGATE(14,6,(ROW(Family_Map!$A$2:$A$35)-ROW(Family_Map!$A$2)+1)/(ISNUMBER(SEARCH(Family_Map!$A$2:$A$35,D7))),1) ), "Other")} -> Other | F7: Intel Core 7 240H | G7: =TRIM(SUBSTITUTE(SUBSTITUTE(SUBSTITUTE(SUBSTITUTE(SUBSTITUTE(F7,"®",""),"™",""),CHAR(160)," "),_xludf.UNICHAR(8203),"")," "," ")) -> #NAME? | H7: =IF(ISNUMBER(SEARCH("CORE ULTRA 9",G7)),"Intel Core Ultra 9", IF(ISNUMBER(SEARCH("CORE ULTRA 7",G7)),"Intel Core Ultra 7",IF(ISNUMBER(SEARCH("CORE I3",G7)),"Intel Core i3", IF(ISNUMBER(SEARCH("CORE ULTRA 5",G7)),"Intel Core Ultra 5", IF(ISNUMBER(SEARCH("CORE I9",G7)),"Intel Core i9", IF(ISNUMBER(SEARCH("CORE I7",G7)),"Intel Core i7", IF(ISNUMBER(SEARCH("CORE I5",G7)),"Intel Core i5", IF(ISNUMBER(SEARCH("CORE 9",G7)),"Intel Core 9", IF(ISNUMBER(SEARCH("CORE 7",G7)),"Intel Core 7", IF(ISNUMBER(SEARCH("CORE 5",G7)),"Intel Core 5", IF(ISNUMBER(SEARCH("RYZEN AI 9",G7)),"AMD Ryzen AI 9", IF(ISNUMBER(SEARCH("RYZEN AI 7",G7)),"AMD Ryzen AI 7", IF(ISNUMBER(SEARCH("RYZEN 9",G7)),"AMD Ryzen 9", IF(ISNUMBER(SEARCH("RYZEN 7",G7)),"AMD Ryzen 7", IF(ISNUMBER(SEARCH("RYZEN 5",G7)),"AMD Ryzen 5", IF(ISNUMBER(SEARCH("SNAPDRAGON",G7)), IF(ISNUMBER(SEARCH("ELITE",G7)),"Snapdragon X Elite", IF(ISNUMBER(SEARCH("PLUS",G7)),"Snapdragon X Plus","Snapdragon")), "Other")))))))))))))))) -> Other | I7: 8 GB GDDR7 | J7: =IFERROR( LEFT( TRIM(MID(I7, MIN(FIND({0,1,2,3,4,5,6,7,8,9}, I7&"0123456789")), 100)), FIND("G", UPPER(TRIM(MID(I7, MIN(FIND({0,1,2,3,4,5,6,7,8,9}, I7&"0123456789")), 100)))) ) & "B", "" ) -> 8 GB | K7: 32GB, 2x16GB, DDR5, 5600 MT/s | L7: =IFERROR( VALUE(SUBSTITUTE(SUBSTITUTE(LEFT(UPPER(TRIM(K7)),FIND("GB",UPPER(K7)&"GB")+1),"GB","")," ","")), IFERROR( VALUE(SUBSTITUTE(SUBSTITUTE(MID(UPPER(K7),FIND("GB",UPPER(K7)&"GB")-3,3),"GB","")," ","")) * IF( OR( ISNUMBER(SEARCH("2X",UPPER(K7))), ISNUMBER(SEARCH("X 2",UPPER(K7))), ISNUMBER(SEARCH("*2",UPPER(K7))), ISNUMBER(SEARCH("2*",UPPER(K7))), ISNUMBER(SEARCH("(2 X",UPPER(K7))) ), 2,1), "") ) -> 32 | M7: 1TB M.2 PCIe NVMe SSD | N7: =IFERROR( LEFT( TRIM(MID(M7, MIN(FIND({0,1,2,3,4,5,6,7,8,9}, M7&"0123456789")), 100)), FIND("B", UPPER(TRIM(MID(M7, MIN(FIND({0,1,2,3,4,5,6,7,8,9}, M7&"0123456789")), 100)))) ), "" ) -> 1TB | O7: =IFERROR( IF(RIGHT(TRIM(N7),2)="TB", VALUE(LEFT(TRIM(N7),LEN(TRIM(N7))-2))*1024 & "GB", TRIM(N7) ), "") -> 1024GB | P7: 2560 x 1600 | Q7: =IFERROR( SUBSTITUTE(SUBSTITUTE(SUBSTITUTE(SUBSTITUTE(SUBSTITUTE(SUBSTITUTE( TRIM(P7), "*","x"),"×","x"),"X","x")," x ","x"),"x ","x")," x","x"), "") -> 2560x1600 | R7: 120 Hz | S7: =IFERROR( TRIM(LEFT(TRIM(R7), FIND(UPPER("H"), UPPER(TRIM(R7)))-1)) & "Hz", "") -> 120Hz | T7: DOS | U7: =IFERROR( IF(AND(ISNUMBER(SEARCH("11",T7)),ISNUMBER(SEARCH("pro",T7))),"Windows 11 Pro", IF(AND(ISNUMBER(SEARCH("10",T7)),ISNUMBER(SEARCH("pro",T7))),"Windows 10 Pro", IF(ISNUMBER(SEARCH("11",T7)),"Windows 11 Home", IF(ISNUMBER(SEARCH("10",T7)),"Windows 10 Home", IF(OR(ISNUMBER(SEARCH("dos",T7)),ISNUMBER(SEARCH("DOS",T7))),"DOS", "Unknown"))))), "Unknown") -> DOS | V7: 2.49 kg | W7: =IFERROR( IF(ISNUMBER(SEARCH(" g",SUBSTITUTE(V7,"gk","kg"))), ROUND(VALUE(TRIM(LEFT(SUBSTITUTE(V7,"gk","kg"),FIND(" ",SUBSTITUTE(V7,"gk","kg"))-1)))/1000,2) & " kg", IF(ISNUMBER(SEARCH("lb",V7)), ROUND(VALUE(TRIM(LEFT(V7,FIND(" ",V7)-1)))*0.453592,2) & " kg", ROUND(VALUE(TRIM(SUBSTITUTE(SUBSTITUTE(SUBSTITUTE(SUBSTITUTE(SUBSTITUTE(V7,"kg",""),"Kg",""),"KG",""),"gk",""),"g",""))),2) & " kg" )), "") -> 2.49 kg | X7: 1 Year | Y7: =IFERROR( IF(ISNUMBER(SEARCH("3",X7)), "3 Years", IF(ISNUMBER(SEARCH("2",X7)), "2 Years", IF(ISNUMBER(SEARCH("1",X7)), "1 Year", "Check Manually"))), "") -> 1 Year | Z7: 67999 | AA7: Unknown | AE7: Brand | AF7: Product Name | AG7: Processor | AH7: Video Graphics | AI7: Video Graphics Memorey
